Workbook
Name mois_par_an: '01_Hypotheses'!$B$7
Name scenario_global: '01_Hypotheses'!$B$5
Name taux_journalier: '01_Hypotheses'!$B$6

Sheet 00_Lisez-moi
A1: Lisez-moi
A2: Donnees generiques. Effort en JH ; Build ponctuel et Run en JH/mois. Cout par fournisseur alternatif ; ne pas additionner les alternatives. Bleu : saisies, noir : calculs, vert : liens, jaune : hypotheses a confirmer.
A4: Cle | B4: Valeur
A5: title | B5: Synthetic web service estimate
A6: date | B6: 2026-10-07
A7: currency | B7: EUR
A8: effort_unit | B8: JH
A9: notes | B9: Entirely synthetic public acceptance example, not a quote. Standard selected; Provider A is a provisional illustration. Build JH and Run JH/month are separate. Provider alternatives must not be added. Forecast FinOps savings require measurement. Kubernetes: Non applicable after suitability review; managed runtime selected. Taxes, discounts, FX and growth excluded; non-cloud OPEX assumed zero. Capacity overloads and delivery overload remain open; this is not an approved production design.

Sheet 01_Hypotheses
A1: Hypotheses
A2: Scenario global et facteurs editables. Les prix synthetiques doivent etre remplaces par des sources datees.
A4: Hypothese | B4: Valeur | C4: Unite | D4: Statut | E4: Source | F4: Notes
A5: scenario_global | B5: Standard | C5: scenario | D5: Confirme | E5: SYN-01 | F5: Global scenario; task overrides take precedence.
A6: taux_journalier | B6: 650 | C6: EUR/JH | D6: A confirmer | E6: SYN-01 | F6: Illustrative rate; replace before a real estimate.
A7: mois_par_an | B7: 12 | C7: mois/an | D7: Confirme | E7: SYN-01 | F7: Annualisation factor.
A8: hours_per_jh | B8: 8 | C8: h/JH | D8: A confirmer | E8: SYN-01 | F8: Editable convention; task estimates already in JH.
A9: schedule.foundation_available | B9: 6 | C9: JH | D9: A confirmer | E9: SYN-01 | F9: Period 1; collective capacity across Foundation roles, not per-role capacity. Owner: delivery lead. Dependency TASK-01 before TASK-02/09/10; individual role availability remains unverified.
A10: schedule.foundation_overload | B10: =SUMIFS(Taches[JH retenu],Taches[Lot],"Foundation",Taches[Nature],"Build")-B9 -> 3 | C10: JH | D10: A confirmer | E10: SYN-01 | F10: Dynamic formula: Foundation Build minus available JH; positive = overload, DEC-SCHEDULE.
A11: capacity.production.Standard.base.cpu | B11: 6 | C11: vCPU | D11: A confirmer | E11: SYN-01 | F11: Assumed aligned CPU demand; independent service scenario and workload band.
A12: capacity.production.Standard.high.cpu | B12: 12 | C12: vCPU | D12: A confirmer | E12: SYN-01 | F12: Assumed high-band CPU demand, not a benchmark.
A13: capacity.production.Standard.base.memory | B13: 8 | C13: GiB | D13: A confirmer | E13: SYN-01 | F13: Synthetic working-set demand; per runtime unit 8 GiB.
A14: capacity.production.Standard.base.storage_gib | B14: 100 | C14: GiB | D14: A confirmer | E14: SYN-01 | F14: Shared usable data demand; backend capacity 200 GiB, not replica-scaled.
A15: capacity.production.Standard.base.iops | B15: 1000 | C15: operations/s | D15: A confirmer | E15: SYN-01 | F15: Shared backend assumed effective 2000 operations/s; latency/mix unmeasured.
A16: capacity.production.Standard.base.bandwidth | B16: 100 | C16: Mbit/s | D16: A confirmer | E16: SYN-01 | F16: Shared link assumed 200 Mbit/s effective; egress envelope is separate pricing.
A17: capacity.production.Standard.base.concurrency | B17: 100 | C17: requests | D17: A confirmer | E17: SYN-01 | F17: Runtime assumed safe 100 concurrent requests/unit; no throughput inferred.
A18: capacity.production.Standard.base.utilisation_target | B18: 0.75 | C18: ratio | D18: A confirmer | E18: SYN-01 | F18: CPU/memory/concurrency target, includes headroom; shared backend requires independent checks.
A19: capacity.production.Standard.base.scaling_limit | B19: 3 | C19: instances | D19: A confirmer | E19: SYN-01 | F19: Hypothetical ceiling; does not make high-band demand feasible.
A20: capacity.production.Standard.base.failure_domain_reserve | B20: 1 | C20: instances | D20: A confirmer | E20: SYN-01 | F20: One runtime loss; does not prove zone/region DR.
A21: capacity.production.Standard.cpu_per_unit | B21: 4 | C21: vCPU/instance | D21: A confirmer | E21: SYN-01 | F21: Effective capacity assumption, not hardware specification.
A22: capacity.production.Standard.units | B22: 2 | C22: instances | D22: A confirmer | E22: SYN-01 | F22: Standard runtime count corresponds to COMP-03 and Provider A Standard cost quantity.
A23: capacity.production.Standard.high.overload_ratio | B23: =B12/(B21*B22*B18) -> 2 | C23: ratio | D23: A confirmer | E23: SYN-01 | F23: Dynamic: high demand / effective CPU at target; >1 infeasible. Other dimensions and failure event require measurement.
A24: contradiction.old_units | B24: 1 | C24: instances | D24: A confirmer | E24: SYN-01 | F24: SYN-02 older single-replica statement; same workload scope.
A25: contradiction.selected_units | B25: 2 | C25: instances | D25: A confirmer | E25: SYN-01 | F25: SYN-03 later resilience requirement; provisional selected branch in DEC-CONFLICT.
A26: contradiction.unit_price | B26: 45 | C26: EUR/instance/month | D26: A confirmer | E26: SYN-01 | F26: Provider A synthetic unit price; not an official tariff.
A27: contradiction.cloud_delta | B27: =(B25-B24)*B26 -> 45 | C27: EUR/mois | D27: A confirmer | E27: SYN-01 | F27: Dynamic selected minus old runtime cost; excludes common envelope/non-production.
A28: contradiction.build_old | B28: 1 | C28: JH | D28: A confirmer | E28: SYN-01 | F28: Single-replica infrastructure branch; mutually exclusive, not included as another task.
A29: contradiction.build_selected | B29: 3 | C29: JH | D29: A confirmer | E29: SYN-01 | F29: Selected infrastructure branch equals TASK-01 Standard net JH.
A30: contradiction.build_delta | B30: =B29-B28 -> 2 | C30: JH | D30: A confirmer | E30: SYN-01 | F30: Dynamic selected minus old Build.
A31: contradiction.run_old | B31: 0.5 | C31: JH/mois | D31: A confirmer | E31: SYN-01 | F31: Old branch monthly operations forecast.
A32: contradiction.run_selected | B32: 1 | C32: JH/mois | D32: A confirmer | E32: SYN-01 | F32: Selected monthly operations equals TASK-06 Standard.
A33: contradiction.run_delta | B33: =B32-B31 -> 0.5 | C33: JH/mois | D33: A confirmer | E33: SYN-01 | F33: Dynamic selected minus old monthly Run.
A34: finops.baseline | B34: 90 | C34: EUR/mois | D34: A confirmer | E34: SYN-01 | F34: Forecast: Development and Staging always-on, two units at Provider A price. No measured billing.
A35: finops.savings_low_fraction | B35: 0.25 | C35: ratio | D35: A confirmer | E35: SYN-01 | F35: Conservative forecast; retains on-demand wakeup.
A36: finops.savings_high_fraction | B36: 0.5 | C36: ratio | D36: A confirmer | E36: SYN-01 | F36: Selected illustrative schedule; recurring costs already include this schedule, do not subtract savings twice.
A37: finops.savings_low | B37: =B34*B35 -> 22.5 | C37: EUR/mois | D37: A confirmer | E37: SYN-01 | F37: Dynamic baseline times low saving fraction.
A38: finops.savings_high | B38: =B34*B36 -> 45 | C38: EUR/mois | D38: A confirmer | E38: SYN-01 | F38: Dynamic baseline times high saving fraction.
A39: finops.savings_selected | B39: =B34-SUMIFS(CoutsCloud[Cout mensuel (EUR)],CoutsCloud[Fournisseur],"Provider A",CoutsCloud[Scenario],"Standard",CoutsCloud[Environnement],"Non-production") -> 45 | C39: EUR/mois | D39: A confirmer | E39: SYN-01 | F39: Dynamic baseline minus scheduled Provider A Standard non-production charges.
A40: tco_horizon_years | B40: 3 | C40: years | D40: A confirmer | E40: SYN-01 | F40: Equal scope and constant demand; taxes, FX, discounts and growth excluded.
A41: non_cloud_opex | B41: 0 | C41: EUR/mois | D41: A confirmer | E41: SYN-01 | F41: Explicit synthetic absence, not an unknown represented as zero.
...

Sheet 02_Inventaire
A1: Inventaire
A2: Inventaire generique des composants et environnements.
A4: ID | B4: Composant | C4: Environnement | D4: Quantite | E4: Unite | F4: Notes
A5: COMP-01 | B5: Web service | C5: Development | D5: 1 | E5: service | F5: Synthetic development workload.
A6: COMP-02 | B6: Web service | C6: Staging | D6: 1 | E6: service | F6: Synthetic validation workload.
A7: COMP-03 | B7: Web service | C7: Production | D7: 2 | E7: replica | F7: Synthetic runtime workload.
A8: COMP-04 | B8: Managed data and platform services | C8: Production | D8: 1 | E8: platform envelope | F8: Usable data, backups, network/egress, logging, registry/build and support; synthetic envelope pricing, not a SKU quote.

Sheet 03_Architecture
A1: Architecture
A2: Options d'architecture et decisions techniques a justifier.
A4: ID | B4: Composant | C4: Type | D4: Environnement | E4: Fournisseur | F4: Decision | G4: Notes
A5: ARCH-01 | B5: Web service | C5: Managed application | D5: Production | E5: Provider A | F5: Managed runtime | G5: Provisional Standard: two runtime replicas. Economique: one, Resilient: three. High workload overload remains open. See DEC-CONFLICT and capacity assumptions.
A6: ARCH-02 | B6: Managed data and platform services | C6: Managed backend | D6: Production | E6: Provider A | F6: Managed backend, separate shared capacity | G6: COMP-04; shared data capacity is not multiplied by runtime replicas. Backup and restore evidence required.
A9: Diagram nodes
A10: ID | B10: Composant | C10: Environnement | D10: Zone | E10: Fournisseur
A11: COMP-01 | B11: Web service | C11: Development | D11: Application | E11: Provider A
A12: COMP-02 | B12: Web service | C12: Staging | D12: Application | E12: Provider A
A13: COMP-03 | B13: Web service | C13: Production | D13: Application | E13: Provider A
A14: COMP-04 | B14: Managed data and platform services | C14: Production | D14: Data | E14: Provider A
A17: Diagram flows
A18: ID | B18: Source | C18: Destination | D18: Flux
A19: FLOW-01 | B19: COMP-03 | C19: COMP-04 | D19: HTTPS (SYN-03)
A22: Icon provenance
A23: Fournisseur | B23: Source officielle | C23: Licence / marque | D23: Fichier | E23: SHA-256
A24: provider-neutral | C24: Original neutral labelled symbols
A27: Diagram manifest
A28: JSON | B28: {"edge_ids": ["FLOW-01"], "icon_provenance": [], "icon_sources": ["provider-neutral"], "node_ids": ["COMP-01", "COMP-02", "COMP-03", "COMP-04"], "output_hashes": {"png": "e0e2ec9c8c883554d77b86ce2bf5b328b61887fce74c656004457b9ae0aa4bf2", "svg": "24f1d21beb26437d7654dcddffaf415355f953121602a68fd44cdb12ef2c2150"}, "warnings": []}

Sheet 04_Taches_JH
A1: Taches_JH
A2: Estimations en JH. Economique = bas, Standard = probable, Resilient = haut. Override local prioritaire ; Build et Run se lisent separement.
A4: ID | B4: Lot | C4: Domaine | D4: Tache | E4: Livrable | F4: Environnement | G4: Role | H4: Prerequis | I4: Dependances | J4: Critere d'acceptation | K4: Preuve attendue | L4: JH bas | M4: JH probable | N4: JH haut | O4: Scenario retenu | P4: Scenario override | Q4: JH retenu | R4: Nature | S4: Couverture | T4: Source | U4: Confiance | V4: Notes
A5: TASK-01 | B5: Foundation | C5: infrastructure | D5: Provision isolated environments | E5: Infrastructure definitions | F5: All | G5: Platform engineer | H5: Approved inventory | J5: Three environments provisioned | K5: Deployment report | L5: 2 | M5: 3 | N5: 5 | O5: =IF(P5="",scenario_global,P5) -> Standard | Q5: =IF(O5="Economique",L5,IF(O5="Standard",M5,N5)) -> 3 | R5: Build | S5: Partial, evidenced synthetic coverage | T5: SYN-01 | U5: Medium | V5: Gross 3/4/6 JH; covered 1/1/1 JH (SYN-02); net 2/3/5 JH. One canonical owner; no aliases.
A6: TASK-02 | B6: Foundation | C6: server-hardening | D6: Apply security baseline | E6: Baseline policy | F6: All | G6: Security engineer | H6: Environments available | I6: TASK-01 | J6: Baseline checks pass | K6: Control report | L6: 1 | M6: 2 | N6: 4 | O6: =IF(P6="",scenario_global,P6) -> Resilient | P6: Resilient | Q6: =IF(O6="Economique",L6,IF(O6="Standard",M6,N6)) -> 4 | R6: Build | S6: Full | T6: SYN-01 | U6: Medium | V6: Explicit task override.
A7: TASK-03 | B7: Delivery | C7: cicd-devsecops | D7: Configure delivery pipeline | E7: Pipeline definitions | F7: All | G7: Delivery engineer | H7: Source repository | I7: TASK-01 | J7: Promote and rollback demonstrated | K7: Pipeline run | L7: 2 | M7: 3 | N7: 5 | O7: =IF(P7="",scenario_global,P7) -> Standard | Q7: =IF(O7="Economique",L7,IF(O7="Standard",M7,N7)) -> 3 | R7: Build | S7: Full | T7: SYN-01 | U7: Medium | V7: Synthetic task.
A8: TASK-04 | B8: Delivery | C8: hosting-capacity | D8: Validate runtime capacity | E8: Capacity report | F8: Staging | G8: Performance engineer | H8: Deployable service | I8: TASK-03 | J8: Staging harness records base/high CPU, memory, storage, IOPS, bandwidth and concurrency; verify target and overload before approval | K8: Synthetic load assumptions now; measured traces, latency percentiles and saturation report required for approval | L8: 1 | M8: 2 | N8: 3 | O8: =IF(P8="",scenario_global,P8) -> Standard | Q8: =IF(O8="Economique",L8,IF(O8="Standard",M8,N8)) -> 2 | R8: Build | S8: Full | T8: SYN-01 | U8: Low | V8: Capacity target to confirm.
A9: TASK-05 | B9: Operations | C9: cloud-migration | D9: Rehearse service transition | E9: Transition runbook | F9: Production | G9: Platform engineer | H9: Validation complete | I9: TASK-02, TASK-04 | J9: Recovery demonstrated | K9: Rehearsal record | L9: 1 | M9: 2 | N9: 4 | O9: =IF(P9="",scenario_global,P9) -> Standard | Q9: =IF(O9="Economique",L9,IF(O9="Standard",M9,N9)) -> 2 | R9: Build | S9: Full | T9: SYN-01 | U9: Medium | V9: Synthetic transition only. Preparation, transfer, integrity, cutover, rollback and owner-only decommissioning in runbook; hypercare is a separate recurring operation. No live source access.
A10: TASK-06 | B10: Operations | C10: finops | D10: Review recurring usage | E10: Usage review | F10: Production | G10: Operations engineer | H10: Usage evidence | I10: TASK-05 | J10: Waste actions recorded | K10: Monthly review | L10: 0.5 | M10: 1 | N10: 2 | O10: =IF(P10="",scenario_global,P10) -> Standard | Q10: =IF(O10="Economique",L10,IF(O10="Standard",M10,N10)) -> 1 | R10: Run | S10: Full | T10: SYN-01 | U10: Medium | V10: Recurring effort in JH/month; kept separate from Build.
A11: TASK-07 | B11: Operations | C11: finops | D11: Schedule non-production runtime | E11: Reversible schedule | F11: All | G11: Platform engineer | H11: Approved inventory | I11: TASK-05 | J11: Forecast; compare metered usage before/after at equal scope; restore always-on schedule on validation failure | K11: Reversible schedule with SYN-01 assumptions | L11: 1 | M11: 2 | N11: 3 | O11: =IF(P11="",scenario_global,P11) -> Standard | Q11: =IF(O11="Economique",L11,IF(O11="Standard",M11,N11)) -> 2 | R11: Build | S11: Full | T11: SYN-01 | U11: Medium | V11: Synthetic net additional Build; one owner and no duplicate deliverable.
A12: TASK-08 | B12: Delivery | C12: architecture-diagram | D12: Reconcile inventory and explicit flows | E12: Embedded diagram and flow register | F12: All | G12: Platform engineer | H12: Approved inventory | I12: TASK-03 | J12: Each node matches inventory; HTTPS edge matches SYN-03; no inferred connection | K12: Embedded diagram and flow register with SYN-01 assumptions | L12: 0.5 | M12: 1 | N12: 2 | O12: =IF(P12="",scenario_global,P12) -> Standard | Q12: =IF(O12="Economique",L12,IF(O12="Standard",M12,N12)) -> 1 | R12: Build | S12: Full | T12: SYN-01 | U12: Medium | V12: Synthetic net additional Build; one owner and no duplicate deliverable.
A13: TASK-09 | B13: Foundation | C13: cloud-architecture | D13: Resolve managed runtime versus cluster suitability | E13: Architecture decision | F13: All | G13: Platform engineer | H13: Approved inventory | I13: TASK-01 | J13: Confirm application isolation, backup and recovery evidence; cluster work excluded because no platform requirement | K13: Architecture decision with SYN-01 assumptions | L13: 0.5 | M13: 1 | N13: 2 | O13: =IF(P13="",scenario_global,P13) -> Standard | Q13: =IF(O13="Economique",L13,IF(O13="Standard",M13,N13)) -> 1 | R13: Build | S13: Full | T13: SYN-01 | U13: Medium | V13: Synthetic net additional Build; one owner and no duplicate deliverable.
A14: TASK-10 | B14: Foundation | C14: provider-selection | D14: Compare equal service scope and three-year TCO | E14: Provider comparison | F14: All | G14: Platform engineer | H14: Approved inventory | I14: TASK-01 | J14: Nine equal-scope alternatives, regional eligibility remains hypothetical; do not approve without official dated quotes | K14: Provider comparison with SYN-01 assumptions | L14: 0.5 | M14: 1 | N14: 2 | O14: =IF(P14="",scenario_global,P14) -> Standard | Q14: =IF(O14="Economique",L14,IF(O14="Standard",M14,N14)) -> 1 | R14: Build | S14: Full | T14: SYN-01 | U14: Medium | V14: Synthetic net additional Build; one owner and no duplicate deliverable.

Sheet 05_Couts_cloud
A1: Couts_cloud
A2: Coûts recurrents par option fournisseur et scenario ; tarifs synthetiques non contractuels. Le multiplicateur convertit l'unite en mois.
A4: ID | B4: Fournisseur | C4: Service | D4: Environnement | E4: Scenario | F4: Unite | G4: Quantite | H4: Prix unitaire (EUR) | I4: Devise | J4: Multiplicateur mensuel | K4: Cout mensuel (EUR) | L4: Cout annuel (EUR) | M4: Source | N4: Confiance | O4: Notes | P4: Statut prix
A5: COST-01 | B5: Provider A | C5: Managed runtime | D5: Production | E5: Economique | F5: unit/month | G5: 1 | H5: 45 | I5: EUR | J5: 1 | K5: =G5*H5*J5 -> 45 | L5: =K5*mois_par_an -> 540 | M5: SYN-01 | N5: Low | O5: Synthetic forecast only; same service perimeter, alternative provider. Replace envelope by verified SKU breakdown before real use. | P5: A confirmer
A6: COST-02 | B6: Provider A | C6: Managed runtime scheduled (Development + Staging) | D6: Non-production | E6: Economique | F6: unit/month | G6: 2 | H6: 45 | I6: EUR | J6: 0.5 | K6: =G6*H6*J6 -> 45 | L6: =K6*mois_par_an -> 540 | M6: SYN-01 | N6: Low | O6: Synthetic forecast only; same service perimeter, alternative provider. Replace envelope by verified SKU breakdown before real use. | P6: A confirmer
A7: COST-03 | B7: Provider A | C7: Managed data, backups, network/egress, logging, build/registry, support | D7: Production | E7: Economique | F7: unit/month | G7: 1 | H7: 24 | I7: EUR | J7: 1 | K7: =G7*H7*J7 -> 24 | L7: =K7*mois_par_an -> 288 | M7: SYN-01 | N7: Low | O7: Synthetic forecast only; same service perimeter, alternative provider. Replace envelope by verified SKU breakdown before real use. | P7: A confirmer
A8: COST-04 | B8: Provider A | C8: Managed runtime | D8: Production | E8: Standard | F8: unit/month | G8: 2 | H8: 45 | I8: EUR | J8: 1 | K8: =G8*H8*J8 -> 90 | L8: =K8*mois_par_an -> 1080 | M8: SYN-01 | N8: Low | O8: Synthetic forecast only; same service perimeter, alternative provider. Replace envelope by verified SKU breakdown before real use. | P8: A confirmer
A9: COST-05 | B9: Provider A | C9: Managed runtime scheduled (Development + Staging) | D9: Non-production | E9: Standard | F9: unit/month | G9: 2 | H9: 45 | I9: EUR | J9: 0.5 | K9: =G9*H9*J9 -> 45 | L9: =K9*mois_par_an -> 540 | M9: SYN-01 | N9: Low | O9: Synthetic forecast only; same service perimeter, alternative provider. Replace envelope by verified SKU breakdown before real use. | P9: A confirmer
A10: COST-06 | B10: Provider A | C10: Managed data, backups, network/egress, logging, build/registry, support | D10: Production | E10: Standard | F10: unit/month | G10: 1 | H10: 36 | I10: EUR | J10: 1 | K10: =G10*H10*J10 -> 36 | L10: =K10*mois_par_an -> 432 | M10: SYN-01 | N10: Low | O10: Synthetic forecast only; same service perimeter, alternative provider. Replace envelope by verified SKU breakdown before real use. | P10: A confirmer
A11: COST-07 | B11: Provider A | C11: Managed runtime | D11: Production | E11: Resilient | F11: unit/month | G11: 3 | H11: 45 | I11: EUR | J11: 1 | K11: =G11*H11*J11 -> 135 | L11: =K11*mois_par_an -> 1620 | M11: SYN-01 | N11: Low | O11: Synthetic forecast only; same service perimeter, alternative provider. Replace envelope by verified SKU breakdown before real use. | P11: A confirmer
A12: COST-08 | B12: Provider A | C12: Managed runtime scheduled (Development + Staging) | D12: Non-production | E12: Resilient | F12: unit/month | G12: 2 | H12: 45 | I12: EUR | J12: 0.5 | K12: =G12*H12*J12 -> 45 | L12: =K12*mois_par_an -> 540 | M12: SYN-01 | N12: Low | O12: Synthetic forecast only; same service perimeter, alternative provider. Replace envelope by verified SKU breakdown before real use. | P12: A confirmer
A13: COST-09 | B13: Provider A | C13: Managed data, backups, network/egress, logging, build/registry, support | D13: Production | E13: Resilient | F13: unit/month | G13: 1 | H13: 60 | I13: EUR | J13: 1 | K13: =G13*H13*J13 -> 60 | L13: =K13*mois_par_an -> 720 | M13: SYN-01 | N13: Low | O13: Synthetic forecast only; same service perimeter, alternative provider. Replace envelope by verified SKU breakdown before real use. | P13: A confirmer
A14: COST-10 | B14: Provider B | C14: Managed runtime | D14: Production | E14: Economique | F14: unit/month | G14: 1 | H14: 50 | I14: EUR | J14: 1 | K14: =G14*H14*J14 -> 50 | L14: =K14*mois_par_an -> 600 | M14: SYN-01 | N14: Low | O14: Synthetic forecast only; same service perimeter, alternative provider. Replace envelope by verified SKU breakdown before real use. | P14: A confirmer
A15: COST-11 | B15: Provider B | C15: Managed runtime scheduled (Development + Staging) | D15: Non-production | E15: Economique | F15: unit/month | G15: 2 | H15: 50 | I15: EUR | J15: 0.5 | K15: =G15*H15*J15 -> 50 | L15: =K15*mois_par_an -> 600 | M15: SYN-01 | N15: Low | O15: Synthetic forecast only; same service perimeter, alternative provider. Replace envelope by verified SKU breakdown before real use. | P15: A confirmer
A16: COST-12 | B16: Provider B | C16: Managed data, backups, network/egress, logging, build/registry, support | D16: Production | E16: Economique | F16: unit/month | G16: 1 | H16: 24 | I16: EUR | J16: 1 | K16: =G16*H16*J16 -> 24 | L16: =K16*mois_par_an -> 288 | M16: SYN-01 | N16: Low | O16: Synthetic forecast only; same service perimeter, alternative provider. Replace envelope by verified SKU breakdown before real use. | P16: A confirmer
... A31: COST-27 | B31: Provider C | C31: Managed data, backups, network/egress, logging, build/registry, support | D31: Production | E31: Resilient | F31: unit/month | G31: 1 | H31: 60 | I31: EUR | J31: 1 | K31: =G31*H31*J31 -> 60 | L31: =K31*mois_par_an -> 720 | M31: SYN-01 | N31: Low | O31: Synthetic forecast only; same service perimeter, alternative provider. Replace envelope by verified SKU breakdown before real use. | P31: A confirmer

Sheet 06_Scenarios
A1: Scenarios
A2: Comparaison sans overrides locaux. Le rapprochement technique additionne JH Build et JH Run/mois, des unites incompatibles : utilisation budgetaire interdite.
A4: Scenario | B4: Description | C4: Rapprochement technique (non budgetaire) | D4: JH Build | E4: JH Run/mois | F4: Notes
A5: Economique | B5: Minimum suitable scope | C5: =SUM(Taches[JH bas]) -> 10 | D5: =SUMIF(Taches[Nature],"Build",Taches[JH bas]) -> 9.5 | E5: =SUMIF(Taches[Nature],"Run",Taches[JH bas]) -> 0.5 | F5: Uses low JH.
A6: Standard | B6: Expected delivery scope | C6: =SUM(Taches[JH probable]) -> 18 | D6: =SUMIF(Taches[Nature],"Build",Taches[JH probable]) -> 17 | E6: =SUMIF(Taches[Nature],"Run",Taches[JH probable]) -> 1 | F6: Uses likely JH.
A7: Resilient | B7: Higher resilience and uncertainty | C7: =SUM(Taches[JH haut]) -> 32 | D7: =SUMIF(Taches[Nature],"Build",Taches[JH haut]) -> 30 | E7: =SUMIF(Taches[Nature],"Run",Taches[JH haut]) -> 2 | F7: Uses high JH.
A10: Comparaison fournisseurs - scenario de reference et horizon dans Hypotheses
A11: Fournisseur | B11: Build (JH) | C11: Run humain (JH/mois) | D11: Cloud (EUR/mois) | E11: Horizon (annees) | F11: TCO (EUR)
A12: Provider A | B12: =IF('01_Hypotheses'!B42="Economique",SUMIFS(Taches[JH bas],Taches[Nature],"Build",Taches[Scenario override],""),IF('01_Hypotheses'!B42="Standard",SUMIFS(Taches[JH probable],Taches[Nature],"Build",Taches[Scenario override],""),SUMIFS(Taches[JH haut],Taches[Nature],"Build",Taches[Scenario override],"")))+SUMIFS(Taches[JH bas],Taches[Nature],"Build",Taches[Scenario override],"Economique")+SUMIFS(Taches[JH probable],Taches[Nature],"Build",Taches[Scenario override],"Standard")+SUMIFS(Taches[JH haut],Taches[Nature],"Build",Taches[Scenario override],"Resilient") -> 19 | C12: =IF('01_Hypotheses'!B42="Economique",SUMIFS(Taches[JH bas],Taches[Nature],"Run",Taches[Scenario override],""),IF('01_Hypotheses'!B42="Standard",SUMIFS(Taches[JH probable],Taches[Nature],"Run",Taches[Scenario override],""),SUMIFS(Taches[JH haut],Taches[Nature],"Run",Taches[Scenario override],"")))+SUMIFS(Taches[JH bas],Taches[Nature],"Run",Taches[Scenario override],"Economique")+SUMIFS(Taches[JH probable],Taches[Nature],"Run",Taches[Scenario override],"Standard")+SUMIFS(Taches[JH haut],Taches[Nature],"Run",Taches[Scenario override],"Resilient") -> 1 | D12: =SUMIFS(CoutsCloud[Cout mensuel (EUR)],CoutsCloud[Fournisseur],A12,CoutsCloud[Scenario],'01_Hypotheses'!B42) -> 171 | E12: ='01_Hypotheses'!B40 -> 3 | F12: =IF(taux_journalier="","",IF(taux_journalier="A chiffrer","",B12*taux_journalier+(C12*taux_journalier+D12+'01_Hypotheses'!B41)*mois_par_an*E12)) -> 41906
A13: Provider B | B13: =IF('01_Hypotheses'!B42="Economique",SUMIFS(Taches[JH bas],Taches[Nature],"Build",Taches[Scenario override],""),IF('01_Hypotheses'!B42="Standard",SUMIFS(Taches[JH probable],Taches[Nature],"Build",Taches[Scenario override],""),SUMIFS(Taches[JH haut],Taches[Nature],"Build",Taches[Scenario override],"")))+SUMIFS(Taches[JH bas],Taches[Nature],"Build",Taches[Scenario override],"Economique")+SUMIFS(Taches[JH probable],Taches[Nature],"Build",Taches[Scenario override],"Standard")+SUMIFS(Taches[JH haut],Taches[Nature],"Build",Taches[Scenario override],"Resilient") -> 19 | C13: =IF('01_Hypotheses'!B42="Economique",SUMIFS(Taches[JH bas],Taches[Nature],"Run",Taches[Scenario override],""),IF('01_Hypotheses'!B42="Standard",SUMIFS(Taches[JH probable],Taches[Nature],"Run",Taches[Scenario override],""),SUMIFS(Taches[JH haut],Taches[Nature],"Run",Taches[Scenario override],"")))+SUMIFS(Taches[JH bas],Taches[Nature],"Run",Taches[Scenario override],"Economique")+SUMIFS(Taches[JH probable],Taches[Nature],"Run",Taches[Scenario override],"Standard")+SUMIFS(Taches[JH haut],Taches[Nature],"Run",Taches[Scenario override],"Resilient") -> 1 | D13: =SUMIFS(CoutsCloud[Cout mensuel (EUR)],CoutsCloud[Fournisseur],A13,CoutsCloud[Scenario],'01_Hypotheses'!B42) -> 186 | E13: ='01_Hypotheses'!B40 -> 3 | F13: =IF(taux_journalier="","",IF(taux_journalier="A chiffrer","",B13*taux_journalier+(C13*taux_journalier+D13+'01_Hypotheses'!B41)*mois_par_an*E13)) -> 42446
A14: Provider C | B14: =IF('01_Hypotheses'!B42="Economique",SUMIFS(Taches[JH bas],Taches[Nature],"Build",Taches[Scenario override],""),IF('01_Hypotheses'!B42="Standard",SUMIFS(Taches[JH probable],Taches[Nature],"Build",Taches[Scenario override],""),SUMIFS(Taches[JH haut],Taches[Nature],"Build",Taches[Scenario override],"")))+SUMIFS(Taches[JH bas],Taches[Nature],"Build",Taches[Scenario override],"Economique")+SUMIFS(Taches[JH probable],Taches[Nature],"Build",Taches[Scenario override],"Standard")+SUMIFS(Taches[JH haut],Taches[Nature],"Build",Taches[Scenario override],"Resilient") -> 19 | C14: =IF('01_Hypotheses'!B42="Economique",SUMIFS(Taches[JH bas],Taches[Nature],"Run",Taches[Scenario override],""),IF('01_Hypotheses'!B42="Standard",SUMIFS(Taches[JH probable],Taches[Nature],"Run",Taches[Scenario override],""),SUMIFS(Taches[JH haut],Taches[Nature],"Run",Taches[Scenario override],"")))+SUMIFS(Taches[JH bas],Taches[Nature],"Run",Taches[Scenario override],"Economique")+SUMIFS(Taches[JH probable],Taches[Nature],"Run",Taches[Scenario override],"Standard")+SUMIFS(Taches[JH haut],Taches[Nature],"Run",Taches[Scenario override],"Resilient") -> 1 | D14: =SUMIFS(CoutsCloud[Cout mensuel (EUR)],CoutsCloud[Fournisseur],A14,CoutsCloud[Scenario],'01_Hypotheses'!B42) -> 201 | E14: ='01_Hypotheses'!B40 -> 3 | F14: =IF(taux_journalier="","",IF(taux_journalier="A chiffrer","",B14*taux_journalier+(C14*taux_journalier+D14+'01_Hypotheses'!B41)*mois_par_an*E14)) -> 42986

Sheet 07_Phasage
A1: Phasage
A2: Lots et jalons. Le rapprochement technique additionne JH Build et JH Run/mois, des unites incompatibles : utilisation budgetaire interdite.
A4: Phase | B4: Sequence | C4: Jalon | D4: Rapprochement technique (non budgetaire) | E4: JH Build | F4: JH Run/mois | G4: Notes
A5: Foundation | B5: 1 | C5: Environments ready | D5: =SUMIF(Taches[Lot],A5,Taches[JH retenu]) -> 9 | E5: =SUMIFS(Taches[JH retenu],Taches[Lot],A5,Taches[Nature],"Build") -> 9 | F5: =SUMIFS(Taches[JH retenu],Taches[Lot],A5,Taches[Nature],"Run") -> 0 | G5: Baseline before delivery.
A6: Delivery | B6: 2 | C6: Service validated | D6: =SUMIF(Taches[Lot],A6,Taches[JH retenu]) -> 6 | E6: =SUMIFS(Taches[JH retenu],Taches[Lot],A6,Taches[Nature],"Build") -> 6 | F6: =SUMIFS(Taches[JH retenu],Taches[Lot],A6,Taches[Nature],"Run") -> 0 | G6: Capacity before transition.
A7: Operations | B7: 3 | C7: Transition complete | D7: =SUMIF(Taches[Lot],A7,Taches[JH retenu]) -> 5 | E7: =SUMIFS(Taches[JH retenu],Taches[Lot],A7,Taches[Nature],"Build") -> 4 | F7: =SUMIFS(Taches[JH retenu],Taches[Lot],A7,Taches[Nature],"Run") -> 1 | G7: Run effort displayed separately.

Sheet 08_Risques
A1: Risques
A2: Incertitudes, impacts et actions de reduction du risque.
A4: ID | B4: Risque | C4: Impact | D4: Probabilite | E4: Mitigation | F4: Responsable | G4: Statut
A5: RISK-01 | B5: Unknown traffic profile | C5: Capacity assumptions may change | D5: Medium | E5: Measure representative load | F5: Performance engineer | G5: Open
A6: RISK-OVERLOAD | B6: High workload CPU exceeds Standard target capacity | C6: Service target infeasible at high band; limited scaling and failure reserve | D6: Assumed | E6: TASK-04 measurement; revisit replicas, quotas and placement before approval | F6: Performance engineer | G6: Open
A7: RISK-SCHEDULE | B7: Foundation delivery overload | C7: Dependent delivery cannot meet provisional period | D7: Certain under forecast | E7: DEC-SCHEDULE; role owner replans capacity before approval | F7: Platform engineer | G7: Open
A8: RISK-FINOPS | B8: Scheduled runtime unavailable during unplanned testing | C8: Wakeup delay | D8: Medium | E8: Retain on-demand wakeup and reversible always-on schedule | F8: Operations engineer | G8: Open

Sheet 09_Arbitrages
A1: Arbitrages
A2: Decisions explicites et hypotheses a confirmer.
A4: ID | B4: Question | C4: Option | D4: Justification | E4: Statut | F4: Source
A5: DEC-01 | B5: Runtime hosting option | C5: Managed runtime | D5: Reduce operational burden | E5: A confirmer | F5: SYN-01
A6: DEC-CONFLICT | B6: SYN-02 single replica conflicts with SYN-03 two replicas | C6: Provisional two-replica branch | D6: Owner: architecture lead; resolve before design approval. See contradiction.* calculation cells for Build, monthly Run and cloud deltas. Single-replica branch accepts outage; only selected branch enters tasks. All three service scenarios keep the same perimeter. | E6: Provisional | F6: SYN-02; SYN-03
A7: DEC-FINOPS | B7: Reduce forecast non-production idle costs | C7: Reversible 50% runtime scheduling forecast | D7: Savings range and selected saving are dynamic finops.* cells. TASK-07 Build and TASK-06 monthly Run. Roll back schedule if wakeup affects testing; meter usage before/after at equal scope. Savings unvalidated; scheduled cost already reflects them. | E7: Forecast, unvalidated | F7: SYN-01
A8: DEC-ARCH | B8: Managed runtime or Kubernetes platform | C8: Managed runtime and shared managed backend | D8: No cluster requirement in this synthetic scope; Kubernetes work Non applicable. Retain application isolation and restore evidence; managed runtime reduces platform ownership, operator monthly Run remains explicit. | E8: Provisional | F8: SYN-01
A9: DEC-SCHEDULE | B9: Foundation Build exceeds Period 1 capacity | C9: Move dependent Foundation work into another period before approval | D9: Dynamic schedule.foundation_overload compares all Foundation Build with collective capacity, not a per-role budget. Delivery lead must confirm collective and individual role availability; subsequent periods cannot start before prerequisites. No approved calendar until overload is resolved. | E9: Open | F9: SYN-01

Sheet 10_Sources
A1: Sources
A2: References datees ; les exemples synthetiques ne constituent pas des tarifs de marche.
A4: ID | B4: Titre | C4: Type | D4: Date | E4: URL | F4: Notes
A5: SYN-01 | B5: Synthetic public assumptions | C5: Synthetic | D5: 2026-10-07 | F5: No client data and no live tariff claims.
A6: SYN-02 | B6: Earlier synthetic single-replica brief and coverage evidence | C6: Synthetic | D6: 2026-10-01 | F6: Invented conflicting requirement and coverage; no private source.
A7: SYN-03 | B7: Later synthetic resilience requirement and flow register | C7: Synthetic | D7: 2026-10-07 | F7: Invented two-replica requirement; FLOW-01 COMP-03 to COMP-04 HTTPS. No live topology.

Sheet 11_Synthese
A1: Synthese
A2: Synthese dynamique des charges et options cloud. Les prix, la couverture et les incertitudes doivent etre confirmes avant engagement.
A4: Indicateur | B4: Valeur | C4: Unite | D4: Notes
A5: Rapprochement technique (Build + Run/mois) | B5: =SUM(Taches[JH retenu]) -> 20 | C5: Unites mixtes | D5: Utilisation budgetaire interdite : JH Build et JH Run/mois ont des unites incompatibles.
A6: JH Build | B6: =SUMIF(Taches[Nature],"Build",Taches[JH retenu]) -> 19 | C6: JH | D6: Effort ponctuel.
A7: JH Run mensuel | B7: =SUMIF(Taches[Nature],"Run",Taches[JH retenu]) -> 1 | C7: JH/mois | D7: Effort recurrent.
A8: Cout Build | B8: =IF(taux_journalier="","",IF(taux_journalier="A chiffrer","",SUMIF(Taches[Nature],"Build",Taches[JH retenu])*taux_journalier)) -> 12350 | C8: EUR | D8: Effort Build au taux journalier saisi.
A9: Cout Run mensuel | B9: =IF(taux_journalier="","",IF(taux_journalier="A chiffrer","",SUMIF(Taches[Nature],"Run",Taches[JH retenu])*taux_journalier)) -> 650 | C9: EUR/mois | D9: Effort Run au taux journalier saisi.
A10: Cloud mensuel | Provider A | Economique | B10: =SUMIFS(CoutsCloud[Cout mensuel (EUR)],CoutsCloud[Fournisseur],"Provider A",CoutsCloud[Scenario],"Economique") -> 114 | C10: EUR/mois | D10: Option alternative ; ne pas sommer les fournisseurs.
A11: Cloud mensuel | Provider A | Standard | B11: =SUMIFS(CoutsCloud[Cout mensuel (EUR)],CoutsCloud[Fournisseur],"Provider A",CoutsCloud[Scenario],"Standard") -> 171 | C11: EUR/mois | D11: Option alternative ; ne pas sommer les fournisseurs.
A12: Cloud mensuel | Provider A | Resilient | B12: =SUMIFS(CoutsCloud[Cout mensuel (EUR)],CoutsCloud[Fournisseur],"Provider A",CoutsCloud[Scenario],"Resilient") -> 240 | C12: EUR/mois | D12: Option alternative ; ne pas sommer les fournisseurs.
A13: Cloud mensuel | Provider B | Economique | B13: =SUMIFS(CoutsCloud[Cout mensuel (EUR)],CoutsCloud[Fournisseur],"Provider B",CoutsCloud[Scenario],"Economique") -> 124 | C13: EUR/mois | D13: Option alternative ; ne pas sommer les fournisseurs.
A14: Cloud mensuel | Provider B | Standard | B14: =SUMIFS(CoutsCloud[Cout mensuel (EUR)],CoutsCloud[Fournisseur],"Provider B",CoutsCloud[Scenario],"Standard") -> 186 | C14: EUR/mois | D14: Option alternative ; ne pas sommer les fournisseurs.
A15: Cloud mensuel | Provider B | Resilient | B15: =SUMIFS(CoutsCloud[Cout mensuel (EUR)],CoutsCloud[Fournisseur],"Provider B",CoutsCloud[Scenario],"Resilient") -> 260 | C15: EUR/mois | D15: Option alternative ; ne pas sommer les fournisseurs.
A16: Cloud mensuel | Provider C | Economique | B16: =SUMIFS(CoutsCloud[Cout mensuel (EUR)],CoutsCloud[Fournisseur],"Provider C",CoutsCloud[Scenario],"Economique") -> 134 | C16: EUR/mois | D16: Option alternative ; ne pas sommer les fournisseurs.
A17: Cloud mensuel | Provider C | Standard | B17: =SUMIFS(CoutsCloud[Cout mensuel (EUR)],CoutsCloud[Fournisseur],"Provider C",CoutsCloud[Scenario],"Standard") -> 201 | C17: EUR/mois | D17: Option alternative ; ne pas sommer les fournisseurs.
A18: Cloud mensuel | Provider C | Resilient | B18: =SUMIFS(CoutsCloud[Cout mensuel (EUR)],CoutsCloud[Fournisseur],"Provider C",CoutsCloud[Scenario],"Resilient") -> 280 | C18: EUR/mois | D18: Option alternative ; ne pas sommer les fournisseurs.
A19: Statut finance | B19: =IF(taux_journalier="","Bloque - taux journalier A chiffrer",IF(taux_journalier="A chiffrer","Bloque - taux journalier A chiffrer","Taux journalier renseigne - approbation non acquise")) -> Taux journalier renseigne - approbation non acquise | C19: Controle | D19: Un taux inconnu bloque couts humains, TCO et approbation financiere, pas les capacites ou JH. Un taux renseigne ne vaut pas approbation.
